Workbook

Sheet Inference
B4: Base Calculation | E4: Model Selection + Cost Estimation
B5: Description | C5: Quantity | E5: Model Name | F5: Input cost($) per 1M token | G5: Output cost($) per 1M token | H5: Cost per input Query($) | I5: Cost per output query Query($) | J5: Total Cost per query | K5: Total cost per month
B6: Email thread / meeting note | C6: 250 | E6: Claude Opus 5.5 | F6: 4 | G6: 20 | H6: =F6*$C$11/1000000 -> 0.0128 | I6: =G6*$C$12/1000000 -> 0.01 | J6: =H6+I6 -> 0.0228 | K6: =Table2[[#This Row],[Total Cost per query]]*$C$16 -> 52.1664
B7: System Prompt | C7: 1500 | E7: Claude Sonnet 5.5 | F7: 2 | G7: 10 | H7: =F7*$C$11/1000000 -> 0.0064 | I7: =G7*$C$12/1000000 -> 0.005 | J7: =H7+I7 -> 0.0114 | K7: =Table2[[#This Row],[Total Cost per query]]*$C$16 -> 26.0832
B8: Team directory + examples | C8: 900 | E8: Claude Haiku 5.5 | F8: 0.1 | G8: 0.5 | H8: =F8*$C$11/1000000 -> 0.00032 | I8: =G8*$C$12/1000000 -> 0.00025 | J8: =H8+I8 -> 0.00057 | K8: =Table2[[#This Row],[Total Cost per query]]*$C$16 -> 1.30416
B9: Matching CRM record(s) | C9: 150
B10: Recent account context | C10: 400
B11: Total input tokens per query | C11: =SUM(C6:C10) -> 3200
B12: Total Output tokens per query | C12: 500
B13: Total Token per query | C13: =C11+C12 -> 3700 | E13: Rows 6-12 describe ONE extraction call: AI reads one email thread or meeting note and returns commitments, deadlines, leads and signals.
B14: Total calls received per day | C14: ='Full Pipeline (added)'!C14 -> 104 | E14: Chosen model for this step: Claude Sonnet 5.5 (row 7). Claude Haiku 5.5 (row 8) runs the cheap relevance filter and brief summaries.
B15: Total number of days per month | C15: 22 | E15: Full monthly cost of every step, batch discount, hosting and scenarios: see the 'Full Pipeline (added)' tab.
B16: Total monthly volume of calls | C16: =C14*C15 -> 2288

Sheet Embeddings
C3: Token/word | D3: 1.3
C5: Emails (sales, per month) | F5: Meeting notes (per month) | I5: CRM records
C6: Component | D6: Quantity | F6: Component | G6: Quantity | I6: Component | J6: Quantity
C7: Number of emails | D7: ='Full Pipeline (added)'!C12*Inference!C15 -> 2112 | F7: Number of notes | G7: ='Full Pipeline (added)'!C13*Inference!C15 -> 176 | I7: Number of CRM records | J7: 40
C8: Number of words per email | D8: 134 | F8: Number of words per note | G8: 99 | I8: Number of words per record | J8: 25
C9: Total number of words | D9: =D7*D8 -> 283008 | F9: Total number of words | G9: =G8*G7 -> 17424 | I9: Total number of words | J9: =J8*J7 -> 1000
C10: Total Tokens | D10: =D9*D3 -> 367910.4 | F10: Total tokens | G10: =G9*D3 -> 22651.2 | I10: Total tokens | J10: =J9*D3 -> 1300
C13: RAG Embeddings
C14: Component | D14: Cost/Quantity
C15: Total tokens for RAG | D15: =D10+G10+J10 -> 391861.6
C16: Cost per 1M token | D16: 0.13
C17: Total cost for RAG | D17: =D15*D16/1000000 -> 0.050942008
C20: User Query Embeddings
C21: Component | D21: Cost/Quantity
C22: Token per user query | D22: 20
C23: Total queries per month | D23: =4*5*Inference!C15 -> 440
C24: Token tokens per month | D24: =D23*D22 -> 8800
C25: Cost per 1M token | D25: 0.13
C26: Total cost for user query embeddings | D26: =D24*D25/1000000 -> 0.001144
C29: Total cost of Embeddings | D29: =D17+D26 -> 0.052086008
C31: NOTE: PromiseKeeper V1 does NOT use embeddings or a vector database. Each AI call already receives the whole thread plus its CRM record (~3,700 tokens).
C32: The figures above size a possible v2 'Ask the account' search feature. Even then the cost is a few cents a month; V1 counts embeddings as $0 (Cost Savings, cell E25).

Sheet Cost Savings
D3: Calculating Human Agent need (manual sales-ops alternative)
D4: Component | E4: Quantity
D5: Documents to review per day | E5: =Inference!C14 -> 104
D6: Documents reviewed per agent/day | E6: 60
D7: Total number of days per month | E7: =Inference!C15 -> 22
D8: Queries handled per month | E8: =E6*E7 -> 1320
D9: Total documents per month | E9: =E5*E7 -> 2288
D10: Number of sales-ops agents required | E10: =E9/E8 -> 1.7333333
D13: Total monthly cost of Human Agents
D14: Component | E14: Cost
D15: Salary | E15: 500
D16: Admin Cost | E16: 100
D17: Total cost per human agent per month | E17: =E15+E16 -> 600
D19: Total cost for Human agent per month | E19: =E17*E10 -> 1040
D22: Cost for PromiseKeeper (AI)
D23: Component | E23: Cost
D24: Inference Cost | E24: ='Full Pipeline (added)'!K21 -> 15.4906
D25: Embeddings Cost | E25: 0
D27: Total PromiseKeeper AI cost | E27: =E24+E25 -> 15.4906
D30: Total Savings | E30: =E19-E27 -> 1024.5094
D31: % Savings | E31: =E30/E19 -> 0.98510519
D33: Reading this sheet: AtliQ would not actually hire sales-ops staff; this is the cost of keeping commitments tracked by hand, which today falls on the founders and Jay.
D34: Hosting (~$45/month in production) and the value of deals protected are on the 'Full Pipeline (added)' and 'Value & Decisions (added)' tabs.

Sheet Full Pipeline (added)
B2: Full pipeline cost: every AI step, hosting, totals and scenarios
B3: Added tab. Extends the template's single-call calculation (Inference tab) to the whole PromiseKeeper pipeline. Blue = assumption, black = formula, green = link.
B5: 1. Volume assumptions (AtliQ's real mailboxes) | E5: 2. Monthly AI cost by pipeline step
B6: Assumption | C6: Value | E6: Step | F6: Model | G6: Input tokens / call | H6: Output tokens / call | I6: Calls / month | J6: Batch? (1/0) | K6: Cost / month ($) | L6: Notes
B7: Sellers (Bhavin, Dhaval, Karandeep, Jay) | C7: 4 | E7: 1. Relevance filter: is this a sales/client email? | F7: Claude Haiku 5.5 | G7: 600 | H7: 30 | I7: =C11*Inference!$C$15 -> 7040 | J7: 1 | K7: =(G7*INDEX(Inference!$F$6:$F$8,MATCH(F7,Inference!$E$6:$E$8,0))+H7*INDEX(Inference!$G$6:$G$8,MATCH(F7,Inference!$E$6:$E$8,0)))/1000000*I7*(1-J7*$C$21)*$C$22 -> 0.264 | L7: Every email. Keeps Sonnet on the ~30% that matter.
B8: Emails per seller per working day (all topics) | C8: 80 | E8: 2. Commitment, deadline, lead and signal extraction | F8: Claude Sonnet 5.5 | G8: =Inference!C11 -> 3200 | H8: =Inference!C12 -> 500 | I8: =Inference!C16 -> 2288 | J8: 1 | K8: =(G8*INDEX(Inference!$F$6:$F$8,MATCH(F8,Inference!$E$6:$E$8,0))+H8*INDEX(Inference!$G$6:$G$8,MATCH(F8,Inference!$E$6:$E$8,0)))/1000000*I8*(1-J8*$C$21)*$C$22 -> 13.0416 | L8: The template's single call (Inference tab), at full volume.
B9: Share that are sales / client threads | C9: 0.3 | E9: 3. Ambiguity / CRM-diff check | F9: Claude Sonnet 5.5 | G9: 1200 | H9: 300 | I9: =C15*Inference!$C$15 -> 330 | J9: 1 | K9: =(G9*INDEX(Inference!$F$6:$F$8,MATCH(F9,Inference!$E$6:$E$8,0))+H9*INDEX(Inference!$G$6:$G$8,MATCH(F9,Inference!$E$6:$E$8,0)))/1000000*I9*(1-J9*$C$21)*$C$22 -> 0.891 | L9: Only when rules cannot decide.
B10: Meeting / call notes per seller per day | C10: 2 | E10: 4. Daily brief summary (per seller + team view) | F10: Claude Haiku 5.5 | G10: 3000 | H10: 800 | I10: =C16*Inference!$C$15 -> 220 | J10: 0 | K10: =(G10*INDEX(Inference!$F$6:$F$8,MATCH(F10,Inference!$E$6:$E$8,0))+H10*INDEX(Inference!$G$6:$G$8,MATCH(F10,Inference!$E$6:$E$8,0)))/1000000*I10*(1-J10*$C$21)*$C$22 -> 0.154 | L10: Also on demand, so standard price. Ranking itself is rules: zero tokens.
B11: Emails per day across the team | C11: =C7*C8 -> 320 | E11: 5. Eval regression on the answer key | F11: Claude Sonnet 5.5 | G11: =Inference!C11 -> 3200 | H11: =Inference!C12 -> 500 | I11: =C17*50 -> 200 | J11: 1 | K11: =(G11*INDEX(Inference!$F$6:$F$8,MATCH(F11,Inference!$E$6:$E$8,0))+H11*INDEX(Inference!$G$6:$G$8,MATCH(F11,Inference!$E$6:$E$8,0)))/1000000*I11*(1-J11*$C$21)*$C$22 -> 1.14 | L11: Keeps the PRD's launch gates honest after prompt changes.
B12: Sales / client emails per day | C12: =ROUND(C11*C9,0) -> 96
B13: Meeting notes per day | C13: =C7*C10 -> 8
B14: Extraction calls per day (feeds Inference!C14) | C14: =C12+C13 -> 104
B15: Ambiguous items needing an extra AI check per day | C15: 15
B16: Brief generations per day (4 sellers + team view + refreshes) | C16: 10
B17: Eval runs per month on the answer key (50 documents each) | C17: 4
B19: Run scheduled steps overnight via Batch API? (1 = yes) | C19: 1
B20: Batch API discount (input and output) | C20: 0.5
B21: Effective batch discount | C21: =C19*C20 -> 0.5 | E21: Total AI (inference) cost per month | K21: =SUM(K7:K11) -> 15.4906
B22: Data-residency multiplier (1.0 none; 1.1 in-region) | C22: 1 | E22: Same, without batch discount | K22: =SUMPRODUCT(K7:K11/(1-J7:J11*$C$21)) -> 30.8272
E25: 3. Infrastructure per month
E26: Component | F26: Prototype (capstone) | G26: Production (V1) | H26: Notes
E27: Web hosting (Next.js app) | F27: 0 | G27: 20 | H27: Vercel free tier / Vercel Pro ~$20 per user per month list price (confirm).
E28: Database + audit log (Postgres) | F28: 0 | G28: 25 | H28: Supabase free tier / Supabase Pro ~$25 per month list price (confirm).
E29: Email + CRM read-only APIs | F29: 0 | G29: 0 | H29: Included in existing workspace and CRM plans.
E30: Nightly scheduler | F30: 0 | G30: 0 | H30: Vercel cron / Supabase scheduled function, included.
E31: Vector DB / embeddings | F31: 0 | G31: 0 | H31: Not used in V1 (Embeddings tab).
E32: Total infrastructure per month | F32: =SUM(F27:F31) -> 0 | G32: =SUM(G27:G31) -> 45
E35: 4. Total cost and unit economics
E36: Measure | F36: Prototype | G36: Production (V1)
E37: AI inference per month | F37: =K21 -> 15.4906 | G37: =K21 -> 15.4906
E38: Infrastructure per month | F38: =F32 -> 0 | G38: =G32 -> 45
E39: Total running cost per month | F39: =F37+F38 -> 15.4906 | G39: =G37+G38 -> 60.4906
E40: Total running cost per year | F40: =F39*12 -> 185.8872 | G40: =G39*12 -> 725.8872
E41: Cost per seller per month | F41: =F39/$C$7 -> 3.87265 | G41: =G39/$C$7 -> 15.12265
E42: Commitments tracked per month (assumption) | F42: 60 | G42: =F42 -> 60
E43: AI cost per commitment tracked | F43: =F37/F42 -> 0.25817667 | G43: =G37/G42 -> 0.25817667
E46: 5. Scenarios
E47: Scenario | F47: AI cost / month | G47: Total (prod.) / month | H47: Comment
E48: Base case | F48: =K21 -> 15.4906 | G48: =F48+$G$32 -> 60.4906 | H48: Haiku + Sonnet mix, nightly batch.
E49: No batch discount (real-time) | F49: =K22 -> 30.8272 | G49: =F49+$G$32 -> 75.8272 | H49: If AtliQ wanted live alerts instead of a morning brief.
...

Sheet Value & Decisions (added)
B2: Value of PromiseKeeper and how cost shaped its scope
B3: Added tab. The template's Cost Savings tab compares against hiring staff; this tab adds founder time returned and deals protected. Blue cells are assumptions to validate in the beta.
B5: 1. Founder / seller time returned | E5: 4. How cost shaped the scope
B6: Component | C6: Value | E6: Decision | F6: Cost impact | G6: Why it is the right product call
B7: Minutes per seller per day on inbox search and 'what's urgent?' | C7: 30 | E7: Two-tier models: Haiku filters every email, Sonnet reads only sales threads | F7: ="Sonnet reads "&TEXT('Full Pipeline (added)'!C14,"0")&" docs/day, not "&TEXT('Full Pipeline (added)'!C11,"0")&"; AI cost "&TEXT('Full Pipeline (added)'!K21,"$0.00")&" vs "&TEXT('Full Pipeline (added)'!F53,"$0.00")&" with no filter" -> Sonnet reads 104 docs/day, not 320; AI cost $15.49 vs $43.58 with no filter | G7: Quality where it matters (quoted extraction), cheap speed where it doesn't.
B8: Minutes per seller per day with the PromiseKeeper brief | C8: 5 | E8: Sonnet 5.5, not Opus 5.5, for extraction | F8: ="All-Opus would cost "&TEXT('Full Pipeline (added)'!F52,"$0.00")&" a month" -> All-Opus would cost $46.87 a month | G8: Structured, quote-checked task; evals decide quality. Opus kept in reserve.
B9: Hours returned per month (4 sellers) | C9: =(C7-C8)*'Full Pipeline (added)'!C7*Inference!C15/60 -> 36.666667 | E9: Nightly Batch API for scheduled steps | F9: ="Saves "&TEXT('Full Pipeline (added)'!K22-'Full Pipeline (added)'!K21,"$0.00")&" a month (50%)" -> Saves $15.34 a month (50%) | G9: Founders need a morning brief, not live alerts, so latency is free to trade.
B10: Jay's reconciliation hours saved per month | C10: 1.75 | E10: Rules, not AI, for dates, ranking and owners | F10: Zero tokens; brief output capped ~800 tokens | G10: Deterministic and explainable.
B11: Value of one founder/seller hour (USD) | C11: 40 | E11: No embeddings / vector DB in V1 | F11: Embeddings tab: cents a month even in v2 | G11: Skipped for simplicity, not money.
B12: Value of time returned per month | C12: =(C9+C10)*C11 -> 1536.6667 | E12: Data residency kept as a visible lever | F12: 1.1x price multiplier | G12: FinEdge requires in-country hosting.
E13: Weekly eval runs budgeted | F13: ="Evals cost "&TEXT('Full Pipeline (added)'!K11,"$0.00")&" a month" -> Evals cost $1.14 a month | G13: PRD launch gates need repeatable measurement.
B15: 2. Revenue protected (expected value, conservative) | E15: Bottom line | F15: ="About "&TEXT('Full Pipeline (added)'!G39,"$0")&" a month in production ("&TEXT('Full Pipeline (added)'!K21,"$0.00")&" of it AI): "&TEXT('Full Pipeline (added)'!G41,"$0.00")&" per seller, against $15,000 for even the smallest deal at risk." -> About $60 a month in production ($15.49 of it AI): $15.12 per seller, against $15,000 for even the smallest deal at risk.
B16: Component | C16: Value
B17: Valued pipeline at risk, 10 Jul 2026 (Step 1) | C17: 423000
B18: Share AtliQ would lose through follow-up failures | C18: 0.3
B19: Share of those losses PromiseKeeper prevents | C19: 0.25
B20: Bookings protected per quarter | C20: =C17*C18*C19 -> 31725
B21: Gross margin on services (assumption) | C21: 0.4
B22: Contribution protected per month | C22: =C20*C21/3 -> 4230
B25: 3. Cost vs value per month (production)
B26: Component | C26: USD / month
B27: PromiseKeeper running cost (AI + hosting) | C27: ='Full Pipeline (added)'!G39 -> 60.4906
B28: Manual sales-ops alternative (Cost Savings tab) | C28: ='Cost Savings'!E19 -> 1040
B29: Value of time returned | C29: =C12 -> 1536.6667
B30: Contribution protected | C30: =C22 -> 4230
B31: Value per $1 spent (time + contribution) | C31: =(C29+C30)/C27 -> 95.331616
